Workbook

Sheet Rekap
A1: REKAP BIAYA MEMBANGUN RUMAH
A2: Tipe 36/72 · 1 lantai · 2 kamar tidur · 1 kamar mandi · paket Menengah · DKI Jakarta · harga Sep 2026
B4: DIKERJAKAN SENDIRI (swakelola) | C4: PAKAI KONTRAKTOR (borongan)
A5: TOTAL BIAYA | B5: ='RAB Swakelola'!J78 -> 2.2567725e+08 | C5: ='RAB Borongan'!L78 -> 2.4478605e+08
A6: Per m² bangunan (item standar) | B6: =SUMIF('RAB Swakelola'!$M$6:$M$71,"Standar",'RAB Swakelola'!$J$6:$J$71)/Volume!$B$23 -> 4645936.1 | C6: =SUMIF('RAB Borongan'!$O$6:$O$71,"Standar",'RAB Borongan'!$L$6:$L$71)/Volume!$B$23 -> 5342826.5
A7: Perkiraan lama pengerjaan | B7: =SUMPRODUCT(MAX('Kurva-S'!$C$6:$C$18+'Kurva-S'!$D$6:$D$18))-1 -> 18 | C7: =B7 -> 18
A8: Yang Anda urus sendiri | B8: Beli bahan, cari & awasi tukang | C8: Hanya mengawasi hasil
A10: RINCIAN | B10: Swakelola | C10: Borongan | D10: Penjelasan
A11: 1. Bahan bangunan | B11: ='RAB Swakelola'!H73-'Perhitungan Bahan'!K77 -> 94881460 | C11: ='RAB Borongan'!I73-'Perhitungan Bahan'!K77 -> 94881460 | D11: Sama untuk kedua cara — rincian di Perhitungan Bahan
A12: 2. Pekerjaan terpasang dari toko/aplikator | B12: ='Perhitungan Bahan'!K77 -> 52305263 | C12: ='Perhitungan Bahan'!K77 -> 52305263 | D12: Baja ringan, kusen & jendela aluminium, septictank, kanopi, pagar
A13: 3. Upah tukang | B13: ='RAB Swakelola'!I73 -> 55534640 | C13: ='RAB Borongan'!J73 -> 55534640 | D13: Sama untuk kedua cara — rincian di Perhitungan Upah
A14: 4. Ongkos kirim bahan | B14: ='RAB Swakelola'!J74 -> 2439776.3 | C14: ='RAB Borongan'!L74 -> 0 | D14: Swakelola: estimasi 3% bahan non-curah. Borongan: termasuk margin
A15: 5. Margin kontraktor | B15: 0 | C15: ='RAB Borongan'!K73 -> 30408204 | D15: ="Overhead + keuntungan kontraktor "&TEXT(Parameter!$B$4,"0%")&" (tidak ada di swakelola)" -> Overhead + keuntungan kontraktor 15% (tidak ada di swakelola)
A16: 6. Dana cadangan | B16: ='RAB Swakelola'!J76 -> 20516114 | C16: ='RAB Borongan'!L76 -> 11656478 | D16: Swakelola 10%, borongan 5%
A17: 7. Pajak | B17: ='RAB Swakelola'!J77 -> 0 | C17: ='RAB Borongan'!L77 -> 0 | D17: Swakelola: PPN KMS bila ≥ 200 m². Borongan: PPN bila kontraktor PKP
A18: TOTAL | B18: =SUM(B11:B17) -> 2.2567725e+08 | C18: =SUM(C11:C17) -> 2.4478605e+08 | D18: =IF(AND(ABS(B18-B5)<1,ABS(C18-C5)<1),"✓ sama dengan total di sheet RAB","periksa RAB") -> ✓ sama dengan total di sheet RAB
A20: PER TAHAP PEKERJAAN | B20: Swakelola | C20: Borongan | D20: Porsi (borongan)
A21: I. PERSIAPAN | B21: ='RAB Swakelola'!J5 -> 4114860 | C21: ='RAB Borongan'!L5 -> 4732089 | D21: =C21/'RAB Borongan'!L73 -> 0.020298107
A22: II. TANAH & PONDASI | B22: ='RAB Swakelola'!J9 -> 17981172 | C22: ='RAB Borongan'!L9 -> 20678348 | D22: =C22/'RAB Borongan'!L73 -> 0.088698949
A23: III. STRUKTUR BETON | B23: ='RAB Swakelola'!J16 -> 15366023 | C23: ='RAB Borongan'!L16 -> 17670927 | D23: =C23/'RAB Borongan'!L73 -> 0.075798736
A24: IV. DINDING | B24: ='RAB Swakelola'!J22 -> 34497221 | C24: ='RAB Borongan'!L22 -> 39671804 | D24: =C24/'RAB Borongan'!L73 -> 0.17017062
A25: V. ATAP | B25: ='RAB Swakelola'!J25 -> 29084268 | C25: ='RAB Borongan'!L25 -> 33446908 | D25: =C25/'RAB Borongan'!L73 -> 0.14346918
A26: VI. PLAFON | B26: ='RAB Swakelola'!J30 -> 4064883.1 | C26: ='RAB Borongan'!L30 -> 4674615.6 | D26: =C26/'RAB Borongan'!L73 -> 0.020051578
A27: VII. LANTAI & KERAMIK | B27: ='RAB Swakelola'!J32 -> 13714771 | C27: ='RAB Borongan'!L32 -> 15771986 | D27: =C27/'RAB Borongan'!L73 -> 0.067653308
A28: VIII. PINTU & JENDELA | B28: ='RAB Swakelola'!J38 -> 18595820 | C28: ='RAB Borongan'!L38 -> 21385193 | D28: =C28/'RAB Borongan'!L73 -> 0.091730934
A29: IX. CAT | B29: ='RAB Swakelola'!J44 -> 10621921 | C29: ='RAB Borongan'!L44 -> 12215210 | D29: =C29/'RAB Borongan'!L73 -> 0.052396655
A30: X. SANITAIR & PLUMBING | B30: ='RAB Swakelola'!J47 -> 14641310 | C30: ='RAB Borongan'!L47 -> 16837506 | D30: =C30/'RAB Borongan'!L73 -> 0.072223813
A31: XI. LISTRIK | B31: ='RAB Swakelola'!J59 -> 8847670 | C31: ='RAB Borongan'!L59 -> 10174820 | D31: =C31/'RAB Borongan'!L73 -> 0.043644488
A32: XII. DAPUR | B32: ='RAB Swakelola'!J63 -> 4492700 | C32: ='RAB Borongan'!L63 -> 5166605 | D32: =C32/'RAB Borongan'!L73 -> 0.022161947
A33: XIII. CARPORT, KANOPI & PAGAR | B33: ='RAB Swakelola'!J65 -> 26698744 | C33: ='RAB Borongan'!L65 -> 30703556 | D33: =C33/'RAB Borongan'!L73 -> 0.13170168
A34: (sebelum ongkos kirim, cadangan & pajak)
A36: HARGA PER m² (pekerjaan standar) | B36: Swakelola | C36: Borongan | D36: Status (paket dipilih di Parameter)
A37: Per m² pekerjaan standar | B37: ='Kontrol Harga'!B13 -> 4645936.1 | C37: ='Kontrol Harga'!B12 -> 5342826.5 | D37: ='Kontrol Harga'!D12 -> Dalam rentang pasar
A38: Rentang wajar pasar | B38: ='Kontrol Harga'!C13 -> 4,347,826 – 6,086,957 | C38: ='Kontrol Harga'!C12 -> 5,000,000 – 7,000,000 | D38: ='Kontrol Harga'!D13 -> Dalam rentang pasar
A39: Upah per m² (setara borongan jasa) | B39: ='Kontrol Harga'!B14 -> 1678954.1 | C39: ='Kontrol Harga'!C14 -> 1,000,000 – 1,800,000 | D39: ='Kontrol Harga'!D14 -> Dalam rentang pasar
A40: Hanya pekerjaan bangunan utama — tanpa toren, pompa, shower set, dapur, carport, kanopi, pagar, ongkos kirim, cadangan & pajak. Rincian di sheet Kontrol Harga.
A42: CATATAN
A43: • Bahan dan upah dihitung sama untuk swakelola dan borongan; bedanya hanya margin kontraktor, ongkos kirim, dana cadangan, dan pajak.
A44: • Swakelola lebih murah, tetapi Anda yang membeli bahan, mencari tukang, dan mengawasi pekerjaan setiap hari.
A45: • Ubah harga bahan di Perhitungan Bahan dan upah harian di Perhitungan Upah — semua sheet ikut berubah.
...

Sheet RAB Swakelola
A1: RAB SWAKELOLA — Tipe 36/72, 1 lantai, paket Menengah, DKI Jakarta (Sep 2026)
A2: Dikerjakan sendiri: bahan + upah (dari AHSP), tanpa margin kontraktor.
A4: No | B4: Pekerjaan | C4: Volume | D4: Sat | E4: Bahan / sat | F4: Upah / sat | G4: Harga satuan | H4: Jumlah bahan | I4: Jumlah upah | J4: JUMLAH HARGA | K4: Keterangan | L4: Referensi | M4: Tipe item
A5: I | B5: PERSIAPAN | H5: =SUM(H6:H8) -> 1608000 | I5: =SUM(I6:I8) -> 2506860 | J5: =SUM(J6:J8) -> 4114860
A6: I.1 | B6: Bouwplank & pengukuran | C6: =AHSP!$K$5 -> 36 | D6: m² | E6: =AHSP!$G$12 -> 3000 | F6: =AHSP!$G$9 -> 15260 | G6: =SUM(E6:F6) -> 18260 | H6: =C6*E6 -> 108000 | I6: =C6*F6 -> 549360 | J6: =C6*G6 -> 657360 | L6: Harga acuan | M6: Standar
A7: I.2 | B7: Pembersihan lahan | C7: =AHSP!$K$17 -> 1 | D7: ls | E7: =AHSP!$G$22 -> 0 | F7: =AHSP!$G$20 -> 1957500 | G7: =SUM(E7:F7) -> 1957500 | H7: =C7*E7 -> 0 | I7: =C7*F7 -> 1957500 | J7: =C7*G7 -> 1957500 | L7: Estimasi | M7: Standar
A8: I.3 | B8: Air & listrik kerja | C8: =AHSP!$K$27 -> 1 | D8: ls | E8: =AHSP!$G$32 -> 1500000 | F8: =AHSP!$G$29 -> 0 | G8: =SUM(E8:F8) -> 1500000 | H8: =C8*E8 -> 1500000 | I8: =C8*F8 -> 0 | J8: =C8*G8 -> 1500000 | L8: Estimasi | M8: Standar
A9: II | B9: TANAH & PONDASI | H9: =SUM(H10:H15) -> 12412117 | I9: =SUM(I10:I15) -> 5569054.4 | J9: =SUM(J10:J15) -> 17981172
A10: II.1 | B10: Galian tanah pondasi | C10: =AHSP!$K$37 -> 24.84 | D10: m³ | E10: =AHSP!$G$43 -> 0 | F10: =AHSP!$G$41 -> 88056.54 | G10: =SUM(E10:F10) -> 88056.54 | H10: =C10*E10 -> 0 | I10: =C10*F10 -> 2187324.5 | J10: =C10*G10 -> 2187324.5 | L10: Harga acuan | M10: Standar
A11: II.2 | B11: Urugan pasir bawah pondasi | C11: =AHSP!$K$48 -> 1.5525 | D11: m³ | E11: =AHSP!$G$55 -> 250800 | F11: =AHSP!$G$52 -> 35218.05 | G11: =SUM(E11:F11) -> 286018.05 | H11: =C11*E11 -> 389367 | I11: =C11*F11 -> 54676.023 | J11: =C11*G11 -> 444043.02 | L11: Harga acuan | M11: Standar
A12: II.3 | B12: Pasangan batu kali 1:4 | C12: =AHSP!$K$60 -> 10.35 | D12: m³ | E12: =AHSP!$G$71 -> 850255.65 | F12: =AHSP!$G$66 -> 215559 | G12: =SUM(E12:F12) -> 1065814.6 | H12: =C12*E12 -> 8800146 | I12: =C12*F12 -> 2231035.6 | J12: =C12*G12 -> 11031182 | L12: Harga acuan | M12: Standar
A13: II.4 | B13: Urugan tanah kembali | C13: =AHSP!$K$76 -> 12.9375 | D13: m³ | E13: =AHSP!$G$82 -> 0 | F13: =AHSP!$G$80 -> 53399.67 | G13: =SUM(E13:F13) -> 53399.67 | H13: =C13*E13 -> 0 | I13: =C13*F13 -> 690858.23 | J13: =C13*G13 -> 690858.23 | L13: Harga acuan | M13: Standar
A14: II.5 | B14: Urugan pasir bawah lantai | C14: =AHSP!$K$87 -> 4.05 | D14: m³ | E14: =AHSP!$G$94 -> 250800 | F14: =AHSP!$G$91 -> 35218.05 | G14: =SUM(E14:F14) -> 286018.05 | H14: =C14*E14 -> 1015740 | I14: =C14*F14 -> 142633.1 | J14: =C14*G14 -> 1158373.1 | L14: Harga acuan | M14: Standar
A15: II.6 | B15: Rabat beton lantai kerja K-175 | C15: =AHSP!$K$99 -> 2.025 | D15: m³ | E15: =AHSP!$G$110 -> 1089809.6 | F15: =AHSP!$G$105 -> 129642.95 | G15: =SUM(E15:F15) -> 1219452.5 | H15: =C15*E15 -> 2206864.4 | I15: =C15*F15 -> 262526.97 | J15: =C15*G15 -> 2469391.3 | L15: Harga acuan | M15: Standar
A16: III | B16: STRUKTUR BETON | H16: =SUM(H17:H21) -> 10978233 | I16: =SUM(I17:I21) -> 4387790.1 | J16: =SUM(J17:J21) -> 15366023
A17: III.1 | B17: Sloof 15×20 (4D10, Ø6-15) | C17: =AHSP!$K$115 -> 1.035 | D17: m³ | E17: =AHSP!$G$135 -> 3356449.5 | F17: =AHSP!$G$123 -> 1341762 | G17: =SUM(E17:F17) -> 4698211.5 | H17: =C17*E17 -> 3473925.2 | I17: =C17*F17 -> 1388723.6 | J17: =C17*G17 -> 4862648.9 | L17: Harga acuan | M17: Standar
A18: III.2 | B18: Kolom 15×15 (4D10, Ø6-15) | C18: =AHSP!$K$140 -> 0.864 | D18: m³ | E18: =AHSP!$G$160 -> 3761682.2 | F18: =AHSP!$G$148 -> 1415137.4 | G18: =SUM(E18:F18) -> 5176819.6 | H18: =C18*E18 -> 3250093.4 | I18: =C18*F18 -> 1222678.7 | J18: =C18*G18 -> 4472772.2 | L18: Harga acuan | M18: Standar
A19: III.3 | B19: Ring balok 12×15 (4D10, Ø6-15) | C19: =AHSP!$K$165 -> 0.621 | D19: m³ | E19: =AHSP!$G$185 -> 4370248.4 | F19: =AHSP!$G$173 -> 1730071.4 | G19: =SUM(E19:F19) -> 6100319.8 | H19: =C19*E19 -> 2713924.3 | I19: =C19*F19 -> 1074374.3 | J19: =C19*G19 -> 3788298.6 | L19: Harga acuan | M19: Standar
A20: III.4 | B20: Balok latei 12×12 (4D8, Ø6-15) | C20: =AHSP!$K$190 -> 0.16272 | D20: m³ | E20: =AHSP!$G$210 -> 4525388.9 | F20: =AHSP!$G$198 -> 2262695.3 | G20: =SUM(E20:F20) -> 6788084.2 | H20: =C20*E20 -> 736371.29 | I20: =C20*F20 -> 368185.78 | J20: =C20*G20 -> 1104557.1 | L20: Harga acuan | M20: Standar
A21: III.5 | B21: Bingkai ampig 12×12 (4D8, Ø6-15) | C21: =AHSP!$K$215 -> 0.19953225 | D21: m³ | E21: =AHSP!$G$235 -> 4029016.5 | F21: =AHSP!$G$223 -> 1673050.9 | G21: =SUM(E21:F21) -> 5702067.5 | H21: =C21*E21 -> 803918.75 | I21: =C21*F21 -> 333827.63 | J21: =C21*G21 -> 1137746.4 | L21: Harga acuan | M21: Standar
A22: IV | B22: DINDING | H22: =SUM(H23:H24) -> 15971058 | I22: =SUM(I23:I24) -> 18526162 | J22: =SUM(J23:J24) -> 34497221
A23: IV.1 | B23: Pasangan bata ringan 10 cm | C23: =AHSP!$K$240 -> 106.5023 | D23: m² | E23: =AHSP!$G$250 -> 105276.86 | F23: =AHSP!$G$246 -> 37256.1 | G23: =SUM(E23:F23) -> 142532.96 | H23: =C23*E23 -> 11212229 | I23: =C23*F23 -> 3967860.5 | J23: =C23*G23 -> 15180089 | L23: Harga acuan | M23: Standar
A24: IV.2 | B24: Plesteran + acian | C24: =AHSP!$K$255 -> 202.6123 | D24: m² | E24: =AHSP!$G$265 -> 23487.368 | F24: =AHSP!$G$261 -> 71853 | G24: =SUM(E24:F24) -> 95340.367 | H24: =C24*E24 -> 4758829.7 | I24: =C24*F24 -> 14558302 | J24: =C24*G24 -> 19317132 | L24: Harga acuan | M24: Standar
A25: V | B25: ATAP | H25: =SUM(H26:H29) -> 22784787 | I25: =SUM(I26:I29) -> 6299480.7 | J25: =SUM(J26:J29) -> 29084268
A26: V.1 | B26: Rangka atap baja ringan | C26: =AHSP!$K$270 -> 59.859676 | D26: m² | E26: =AHSP!$G$274 -> 201600 | F26: =AHSP!$G$271 -> 0 | G26: =SUM(E26:F26) -> 201600 | H26: =C26*E26 -> 12067711 | I26: =C26*F26 -> 0 | J26: =C26*G26 -> 12067711 | K26: Terpasang (termasuk jasa pasang) | L26: Harga acuan | M26: Standar
A27: V.2 | B27: Genteng beton | C27: =AHSP!$K$279 -> 59.859676 | D27: m² | E27: =AHSP!$G$286 -> 128235 | F27: =AHSP!$G$283 -> 100505 | G27: =SUM(E27:F27) -> 228740 | H27: =C27*E27 -> 7676105.5 | I27: =C27*F27 -> 6016196.7 | J27: =C27*G27 -> 13692302 | L27: Harga acuan | M27: Standar
A28: V.3 | B28: Nok / bubungan | C28: =AHSP!$K$291 -> 7.2 | D28: m' | E28: =AHSP!$G$300 -> 34510.95 | F28: =AHSP!$G$295 -> 39345 | G28: =SUM(E28:F28) -> 73855.95 | H28: =C28*E28 -> 248478.84 | I28: =C28*F28 -> 283284 | J28: =C28*G28 -> 531762.84 | L28: Harga acuan | M28: Standar
A29: V.4 | B29: Lisplang GRC 20 cm | C29: =AHSP!$K$305 -> 31.027688 | D29: m' | E29: =AHSP!$G$309 -> 90000 | F29: =AHSP!$G$306 -> 0 | G29: =SUM(E29:F29) -> 90000 | H29: =C29*E29 -> 2792491.9 | I29: =C29*F29 -> 0 | J29: =C29*G29 -> 2792491.9 | K29: Terpasang (termasuk jasa pasang) | L29: Estimasi | M29: Standar
A30: VI | B30: PLAFON | H30: =SUM(H31:H31) -> 2121288.1 | I30: =SUM(I31:I31) -> 1943595 | J30: =SUM(J31:J31) -> 4064883.1
A31: VI.1 | B31: Plafon gypsum 9 mm + rangka hollow | C31: =AHSP!$K$314 -> 40.5 | D31: m² | E31: =AHSP!$G$323 -> 52377.485 | F31: =AHSP!$G$318 -> 47990 | G31: =SUM(E31:F31) -> 100367.49 | H31: =C31*E31 -> 2121288.1 | I31: =C31*F31 -> 1943595 | J31: =C31*G31 -> 4064883.1 | L31: Harga acuan | M31: Standar
A32: VII | B32: LANTAI & KERAMIK | H32: =SUM(H33:H37) -> 8799479.4 | I32: =SUM(I33:I37) -> 4915291.5 | J32: =SUM(J33:J37) -> 13714771
A33: VII.1 | B33: Granit HT 60×60 | C33: =AHSP!$K$328 -> 29.55 | D33: m² | E33: =AHSP!$G$338 -> 177837.4 | F33: =AHSP!$G$332 -> 74775 | G33: =SUM(E33:F33) -> 252612.4 | H33: =C33*E33 -> 5255095.2 | I33: =C33*F33 -> 2209601.2 | J33: =C33*G33 -> 7464696.4 | L33: Harga acuan | M33: Standar
A34: VII.2 | B34: Plint granit (potongan 10 cm) | C34: =AHSP!$K$343 -> 61 | D34: m' | E34: =AHSP!$G$352 -> 16622.5 | F34: =AHSP!$G$347 -> 19896.5 | G34: =SUM(E34:F34) -> 36519 | H34: =C34*E34 -> 1013972.5 | I34: =C34*F34 -> 1213686.5 | J34: =C34*G34 -> 2227659 | L34: Harga acuan | M34: Standar
A35: VII.3 | B35: Keramik lantai KM anti-slip | C35: =AHSP!$K$357 -> 3 | D35: m² | E35: =AHSP!$G$367 -> 139649.9 | F35: =AHSP!$G$361 -> 65153 | G35: =SUM(E35:F35) -> 204802.9 | H35: =C35*E35 -> 418949.7 | I35: =C35*F35 -> 195459 | J35: =C35*G35 -> 614408.7 | L35: Harga acuan | M35: Standar
A36: VII.4 | B36: Keramik dinding KM | C36: =AHSP!$K$372 -> 15.4 | D36: m² | E36: =AHSP!$G$382 -> 105724.84 | F36: =AHSP!$G$376 -> 65153 | G36: =SUM(E36:F36) -> 170877.83 | H36: =C36*E36 -> 1628162.5 | I36: =C36*F36 -> 1003356.2 | J36: =C36*G36 -> 2631518.7 | L36: Harga acuan | M36: Standar
A37: VII.5 | B37: Keramik teras 40×40 | C37: =AHSP!$K$387 -> 4.5 | D37: m² | E37: =AHSP!$G$397 -> 107399.9 | F37: =AHSP!$G$391 -> 65153 | G37: =SUM(E37:F37) -> 172552.9 | H37: =C37*E37 -> 483299.55 | I37: =C37*F37 -> 293188.5 | J37: =C37*G37 -> 776488.05 | L37: Harga acuan | M37: Standar
A38: VIII | B38: PINTU & JENDELA | H38: =SUM(H39:H43) -> 17740420 | I38: =SUM(I39:I43) -> 855400 | J38: =SUM(J39:J43) -> 18595820
A39: VIII.1 | B39: Pintu utama aluminium + kusen + kunci | C39: =AHSP!$K$402 -> 1 | D39: unit | E39: =AHSP!$G$406 -> 2796200 | F39: =AHSP!$G$403 -> 0 | G39: =SUM(E39:F39) -> 2796200 | H39: =C39*E39 -> 2796200 | I39: =C39*F39 -> 0 | J39: =C39*G39 -> 2796200 | K39: Terpasang (termasuk jasa pasang) | L39: Harga acuan | M39: Standar
A40: VIII.2 | B40: Pintu kamar HPL + kusen aluminium (2 kamar + belakang) | C40: =AHSP!$K$411 -> 3 | D40: unit | E40: =AHSP!$G$420 -> 1631200 | F40: =AHSP!$G$415 -> 213850 | G40: =SUM(E40:F40) -> 1845050 | H40: =C40*E40 -> 4893600 | I40: =C40*F40 -> 641550 | J40: =C40*G40 -> 5535150 | L40: Harga acuan | M40: Standar
A41: VIII.3 | B41: Pintu KM PVC | C41: =AHSP!$K$425 -> 1 | D41: unit | E41: =AHSP!$G$432 -> 949900 | F41: =AHSP!$G$429 -> 213850 | G41: =SUM(E41:F41) -> 1163750 | H41: =C41*E41 -> 949900 | I41: =C41*F41 -> 213850 | J41: =C41*G41 -> 1163750 | L41: Harga acuan | M41: Standar
...

Sheet RAB Borongan
A1: RAB BORONGAN — Tipe 36/72, 1 lantai, paket Menengah, DKI Jakarta (Sep 2026)
A2: Dikerjakan kontraktor: bahan + upah (dari AHSP) + margin kontraktor.
A4: No | B4: Pekerjaan | C4: Volume | D4: Sat | E4: Bahan / sat | F4: Upah / sat | G4: Margin / sat | H4: Harga satuan | I4: Jumlah bahan | J4: Jumlah upah | K4: Jumlah margin | L4: JUMLAH HARGA | M4: Keterangan | N4: Referensi | O4: Tipe item
A5: I | B5: PERSIAPAN | I5: =SUM(I6:I8) -> 1608000 | J5: =SUM(J6:J8) -> 2506860 | K5: =SUM(K6:K8) -> 617229 | L5: =SUM(L6:L8) -> 4732089
A6: I.1 | B6: Bouwplank & pengukuran | C6: =AHSP!$K$5 -> 36 | D6: m² | E6: =AHSP!$G$12 -> 3000 | F6: =AHSP!$G$9 -> 15260 | G6: =AHSP!$G$14 -> 2739 | H6: =SUM(E6:G6) -> 20999 | I6: =C6*E6 -> 108000 | J6: =C6*F6 -> 549360 | K6: =C6*G6 -> 98604 | L6: =C6*H6 -> 755964 | N6: Harga acuan | O6: Standar
A7: I.2 | B7: Pembersihan lahan | C7: =AHSP!$K$17 -> 1 | D7: ls | E7: =AHSP!$G$22 -> 0 | F7: =AHSP!$G$20 -> 1957500 | G7: =AHSP!$G$24 -> 293625 | H7: =SUM(E7:G7) -> 2251125 | I7: =C7*E7 -> 0 | J7: =C7*F7 -> 1957500 | K7: =C7*G7 -> 293625 | L7: =C7*H7 -> 2251125 | N7: Estimasi | O7: Standar
A8: I.3 | B8: Air & listrik kerja | C8: =AHSP!$K$27 -> 1 | D8: ls | E8: =AHSP!$G$32 -> 1500000 | F8: =AHSP!$G$29 -> 0 | G8: =AHSP!$G$34 -> 225000 | H8: =SUM(E8:G8) -> 1725000 | I8: =C8*E8 -> 1500000 | J8: =C8*F8 -> 0 | K8: =C8*G8 -> 225000 | L8: =C8*H8 -> 1725000 | N8: Estimasi | O8: Standar
A9: II | B9: TANAH & PONDASI | I9: =SUM(I10:I15) -> 12412117 | J9: =SUM(J10:J15) -> 5569054.4 | K9: =SUM(K10:K15) -> 2697175.8 | L9: =SUM(L10:L15) -> 20678348
A10: II.1 | B10: Galian tanah pondasi | C10: =AHSP!$K$37 -> 24.84 | D10: m³ | E10: =AHSP!$G$43 -> 0 | F10: =AHSP!$G$41 -> 88056.54 | G10: =AHSP!$G$45 -> 13208.481 | H10: =SUM(E10:G10) -> 101265.02 | I10: =C10*E10 -> 0 | J10: =C10*F10 -> 2187324.5 | K10: =C10*G10 -> 328098.67 | L10: =C10*H10 -> 2515423.1 | N10: Harga acuan | O10: Standar
A11: II.2 | B11: Urugan pasir bawah pondasi | C11: =AHSP!$K$48 -> 1.5525 | D11: m³ | E11: =AHSP!$G$55 -> 250800 | F11: =AHSP!$G$52 -> 35218.05 | G11: =AHSP!$G$57 -> 42902.707 | H11: =SUM(E11:G11) -> 328920.76 | I11: =C11*E11 -> 389367 | J11: =C11*F11 -> 54676.023 | K11: =C11*G11 -> 66606.453 | L11: =C11*H11 -> 510649.48 | N11: Harga acuan | O11: Standar
A12: II.3 | B12: Pasangan batu kali 1:4 | C12: =AHSP!$K$60 -> 10.35 | D12: m³ | E12: =AHSP!$G$71 -> 850255.65 | F12: =AHSP!$G$66 -> 215559 | G12: =AHSP!$G$73 -> 159872.2 | H12: =SUM(E12:G12) -> 1225686.8 | I12: =C12*E12 -> 8800146 | J12: =C12*F12 -> 2231035.6 | K12: =C12*G12 -> 1654677.2 | L12: =C12*H12 -> 12685859 | N12: Harga acuan | O12: Standar
A13: II.4 | B13: Urugan tanah kembali | C13: =AHSP!$K$76 -> 12.9375 | D13: m³ | E13: =AHSP!$G$82 -> 0 | F13: =AHSP!$G$80 -> 53399.67 | G13: =AHSP!$G$84 -> 8009.9505 | H13: =SUM(E13:G13) -> 61409.62 | I13: =C13*E13 -> 0 | J13: =C13*F13 -> 690858.23 | K13: =C13*G13 -> 103628.73 | L13: =C13*H13 -> 794486.97 | N13: Harga acuan | O13: Standar
A14: II.5 | B14: Urugan pasir bawah lantai | C14: =AHSP!$K$87 -> 4.05 | D14: m³ | E14: =AHSP!$G$94 -> 250800 | F14: =AHSP!$G$91 -> 35218.05 | G14: =AHSP!$G$96 -> 42902.707 | H14: =SUM(E14:G14) -> 328920.76 | I14: =C14*E14 -> 1015740 | J14: =C14*F14 -> 142633.1 | K14: =C14*G14 -> 173755.97 | L14: =C14*H14 -> 1332129.1 | N14: Harga acuan | O14: Standar
A15: II.6 | B15: Rabat beton lantai kerja K-175 | C15: =AHSP!$K$99 -> 2.025 | D15: m³ | E15: =AHSP!$G$110 -> 1089809.6 | F15: =AHSP!$G$105 -> 129642.95 | G15: =AHSP!$G$112 -> 182917.88 | H15: =SUM(E15:G15) -> 1402370.4 | I15: =C15*E15 -> 2206864.4 | J15: =C15*F15 -> 262526.97 | K15: =C15*G15 -> 370408.7 | L15: =C15*H15 -> 2839800 | N15: Harga acuan | O15: Standar
A16: III | B16: STRUKTUR BETON | I16: =SUM(I17:I21) -> 10978233 | J16: =SUM(J17:J21) -> 4387790.1 | K16: =SUM(K17:K21) -> 2304903.5 | L16: =SUM(L17:L21) -> 17670927
A17: III.1 | B17: Sloof 15×20 (4D10, Ø6-15) | C17: =AHSP!$K$115 -> 1.035 | D17: m³ | E17: =AHSP!$G$135 -> 3356449.5 | F17: =AHSP!$G$123 -> 1341762 | G17: =AHSP!$G$137 -> 704731.72 | H17: =SUM(E17:G17) -> 5402943.2 | I17: =C17*E17 -> 3473925.2 | J17: =C17*F17 -> 1388723.6 | K17: =C17*G17 -> 729397.33 | L17: =C17*H17 -> 5592046.2 | N17: Harga acuan | O17: Standar
A18: III.2 | B18: Kolom 15×15 (4D10, Ø6-15) | C18: =AHSP!$K$140 -> 0.864 | D18: m³ | E18: =AHSP!$G$160 -> 3761682.2 | F18: =AHSP!$G$148 -> 1415137.4 | G18: =AHSP!$G$162 -> 776522.94 | H18: =SUM(E18:G18) -> 5953342.6 | I18: =C18*E18 -> 3250093.4 | J18: =C18*F18 -> 1222678.7 | K18: =C18*G18 -> 670915.82 | L18: =C18*H18 -> 5143688 | N18: Harga acuan | O18: Standar
A19: III.3 | B19: Ring balok 12×15 (4D10, Ø6-15) | C19: =AHSP!$K$165 -> 0.621 | D19: m³ | E19: =AHSP!$G$185 -> 4370248.4 | F19: =AHSP!$G$173 -> 1730071.4 | G19: =AHSP!$G$187 -> 915047.98 | H19: =SUM(E19:G19) -> 7015367.8 | I19: =C19*E19 -> 2713924.3 | J19: =C19*F19 -> 1074374.3 | K19: =C19*G19 -> 568244.79 | L19: =C19*H19 -> 4356543.4 | N19: Harga acuan | O19: Standar
A20: III.4 | B20: Balok latei 12×12 (4D8, Ø6-15) | C20: =AHSP!$K$190 -> 0.16272 | D20: m³ | E20: =AHSP!$G$210 -> 4525388.9 | F20: =AHSP!$G$198 -> 2262695.3 | G20: =AHSP!$G$212 -> 1018212.6 | H20: =SUM(E20:G20) -> 7806296.8 | I20: =C20*E20 -> 736371.29 | J20: =C20*F20 -> 368185.78 | K20: =C20*G20 -> 165683.56 | L20: =C20*H20 -> 1270240.6 | N20: Harga acuan | O20: Standar
A21: III.5 | B21: Bingkai ampig 12×12 (4D8, Ø6-15) | C21: =AHSP!$K$215 -> 0.19953225 | D21: m³ | E21: =AHSP!$G$235 -> 4029016.5 | F21: =AHSP!$G$223 -> 1673050.9 | G21: =AHSP!$G$237 -> 855310.12 | H21: =SUM(E21:G21) -> 6557377.6 | I21: =C21*E21 -> 803918.75 | J21: =C21*F21 -> 333827.63 | K21: =C21*G21 -> 170661.96 | L21: =C21*H21 -> 1308408.3 | N21: Harga acuan | O21: Standar
A22: IV | B22: DINDING | I22: =SUM(I23:I24) -> 15971058 | J22: =SUM(J23:J24) -> 18526162 | K22: =SUM(K23:K24) -> 5174583.1 | L22: =SUM(L23:L24) -> 39671804
A23: IV.1 | B23: Pasangan bata ringan 10 cm | C23: =AHSP!$K$240 -> 106.5023 | D23: m² | E23: =AHSP!$G$250 -> 105276.86 | F23: =AHSP!$G$246 -> 37256.1 | G23: =AHSP!$G$252 -> 21379.945 | H23: =SUM(E23:G23) -> 163912.91 | I23: =C23*E23 -> 11212229 | J23: =C23*F23 -> 3967860.5 | K23: =C23*G23 -> 2277013.4 | L23: =C23*H23 -> 17457103 | N23: Harga acuan | O23: Standar
A24: IV.2 | B24: Plesteran + acian | C24: =AHSP!$K$255 -> 202.6123 | D24: m² | E24: =AHSP!$G$265 -> 23487.368 | F24: =AHSP!$G$261 -> 71853 | G24: =AHSP!$G$267 -> 14301.055 | H24: =SUM(E24:G24) -> 109641.42 | I24: =C24*E24 -> 4758829.7 | J24: =C24*F24 -> 14558302 | K24: =C24*G24 -> 2897569.7 | L24: =C24*H24 -> 22214701 | N24: Harga acuan | O24: Standar
A25: V | B25: ATAP | I25: =SUM(I26:I29) -> 22784787 | J25: =SUM(J26:J29) -> 6299480.7 | K25: =SUM(K26:K29) -> 4362640.2 | L25: =SUM(L26:L29) -> 33446908
A26: V.1 | B26: Rangka atap baja ringan | C26: =AHSP!$K$270 -> 59.859676 | D26: m² | E26: =AHSP!$G$274 -> 201600 | F26: =AHSP!$G$271 -> 0 | G26: =AHSP!$G$276 -> 30240 | H26: =SUM(E26:G26) -> 231840 | I26: =C26*E26 -> 12067711 | J26: =C26*F26 -> 0 | K26: =C26*G26 -> 1810156.6 | L26: =C26*H26 -> 13877867 | M26: Terpasang (termasuk jasa pasang) | N26: Harga acuan | O26: Standar
A27: V.2 | B27: Genteng beton | C27: =AHSP!$K$279 -> 59.859676 | D27: m² | E27: =AHSP!$G$286 -> 128235 | F27: =AHSP!$G$283 -> 100505 | G27: =AHSP!$G$288 -> 34311 | H27: =SUM(E27:G27) -> 263051 | I27: =C27*E27 -> 7676105.5 | J27: =C27*F27 -> 6016196.7 | K27: =C27*G27 -> 2053845.3 | L27: =C27*H27 -> 15746148 | N27: Harga acuan | O27: Standar
A28: V.3 | B28: Nok / bubungan | C28: =AHSP!$K$291 -> 7.2 | D28: m' | E28: =AHSP!$G$300 -> 34510.95 | F28: =AHSP!$G$295 -> 39345 | G28: =AHSP!$G$302 -> 11078.392 | H28: =SUM(E28:G28) -> 84934.342 | I28: =C28*E28 -> 248478.84 | J28: =C28*F28 -> 283284 | K28: =C28*G28 -> 79764.426 | L28: =C28*H28 -> 611527.27 | N28: Harga acuan | O28: Standar
A29: V.4 | B29: Lisplang GRC 20 cm | C29: =AHSP!$K$305 -> 31.027688 | D29: m' | E29: =AHSP!$G$309 -> 90000 | F29: =AHSP!$G$306 -> 0 | G29: =AHSP!$G$311 -> 13500 | H29: =SUM(E29:G29) -> 103500 | I29: =C29*E29 -> 2792491.9 | J29: =C29*F29 -> 0 | K29: =C29*G29 -> 418873.78 | L29: =C29*H29 -> 3211365.7 | M29: Terpasang (termasuk jasa pasang) | N29: Estimasi | O29: Standar
A30: VI | B30: PLAFON | I30: =SUM(I31:I31) -> 2121288.1 | J30: =SUM(J31:J31) -> 1943595 | K30: =SUM(K31:K31) -> 609732.47 | L30: =SUM(L31:L31) -> 4674615.6
A31: VI.1 | B31: Plafon gypsum 9 mm + rangka hollow | C31: =AHSP!$K$314 -> 40.5 | D31: m² | E31: =AHSP!$G$323 -> 52377.485 | F31: =AHSP!$G$318 -> 47990 | G31: =AHSP!$G$325 -> 15055.123 | H31: =SUM(E31:G31) -> 115422.61 | I31: =C31*E31 -> 2121288.1 | J31: =C31*F31 -> 1943595 | K31: =C31*G31 -> 609732.47 | L31: =C31*H31 -> 4674615.6 | N31: Harga acuan | O31: Standar
A32: VII | B32: LANTAI & KERAMIK | I32: =SUM(I33:I37) -> 8799479.4 | J32: =SUM(J33:J37) -> 4915291.5 | K32: =SUM(K33:K37) -> 2057215.6 | L32: =SUM(L33:L37) -> 15771986
A33: VII.1 | B33: Granit HT 60×60 | C33: =AHSP!$K$328 -> 29.55 | D33: m² | E33: =AHSP!$G$338 -> 177837.4 | F33: =AHSP!$G$332 -> 74775 | G33: =AHSP!$G$340 -> 37891.86 | H33: =SUM(E33:G33) -> 290504.26 | I33: =C33*E33 -> 5255095.2 | J33: =C33*F33 -> 2209601.2 | K33: =C33*G33 -> 1119704.5 | L33: =C33*H33 -> 8584400.9 | N33: Harga acuan | O33: Standar
A34: VII.2 | B34: Plint granit (potongan 10 cm) | C34: =AHSP!$K$343 -> 61 | D34: m' | E34: =AHSP!$G$352 -> 16622.5 | F34: =AHSP!$G$347 -> 19896.5 | G34: =AHSP!$G$354 -> 5477.85 | H34: =SUM(E34:G34) -> 41996.85 | I34: =C34*E34 -> 1013972.5 | J34: =C34*F34 -> 1213686.5 | K34: =C34*G34 -> 334148.85 | L34: =C34*H34 -> 2561807.9 | N34: Harga acuan | O34: Standar
A35: VII.3 | B35: Keramik lantai KM anti-slip | C35: =AHSP!$K$357 -> 3 | D35: m² | E35: =AHSP!$G$367 -> 139649.9 | F35: =AHSP!$G$361 -> 65153 | G35: =AHSP!$G$369 -> 30720.435 | H35: =SUM(E35:G35) -> 235523.33 | I35: =C35*E35 -> 418949.7 | J35: =C35*F35 -> 195459 | K35: =C35*G35 -> 92161.305 | L35: =C35*H35 -> 706570.01 | N35: Harga acuan | O35: Standar
A36: VII.4 | B36: Keramik dinding KM | C36: =AHSP!$K$372 -> 15.4 | D36: m² | E36: =AHSP!$G$382 -> 105724.84 | F36: =AHSP!$G$376 -> 65153 | G36: =AHSP!$G$384 -> 25631.675 | H36: =SUM(E36:G36) -> 196509.51 | I36: =C36*E36 -> 1628162.5 | J36: =C36*F36 -> 1003356.2 | K36: =C36*G36 -> 394727.8 | L36: =C36*H36 -> 3026246.5 | N36: Harga acuan | O36: Standar
A37: VII.5 | B37: Keramik teras 40×40 | C37: =AHSP!$K$387 -> 4.5 | D37: m² | E37: =AHSP!$G$397 -> 107399.9 | F37: =AHSP!$G$391 -> 65153 | G37: =AHSP!$G$399 -> 25882.935 | H37: =SUM(E37:G37) -> 198435.83 | I37: =C37*E37 -> 483299.55 | J37: =C37*F37 -> 293188.5 | K37: =C37*G37 -> 116473.21 | L37: =C37*H37 -> 892961.26 | N37: Harga acuan | O37: Standar
A38: VIII | B38: PINTU & JENDELA | I38: =SUM(I39:I43) -> 17740420 | J38: =SUM(J39:J43) -> 855400 | K38: =SUM(K39:K43) -> 2789373 | L38: =SUM(L39:L43) -> 21385193
A39: VIII.1 | B39: Pintu utama aluminium + kusen + kunci | C39: =AHSP!$K$402 -> 1 | D39: unit | E39: =AHSP!$G$406 -> 2796200 | F39: =AHSP!$G$403 -> 0 | G39: =AHSP!$G$408 -> 419430 | H39: =SUM(E39:G39) -> 3215630 | I39: =C39*E39 -> 2796200 | J39: =C39*F39 -> 0 | K39: =C39*G39 -> 419430 | L39: =C39*H39 -> 3215630 | M39: Terpasang (termasuk jasa pasang) | N39: Harga acuan | O39: Standar
A40: VIII.2 | B40: Pintu kamar HPL + kusen aluminium (2 kamar + belakang) | C40: =AHSP!$K$411 -> 3 | D40: unit | E40: =AHSP!$G$420 -> 1631200 | F40: =AHSP!$G$415 -> 213850 | G40: =AHSP!$G$422 -> 276757.5 | H40: =SUM(E40:G40) -> 2121807.5 | I40: =C40*E40 -> 4893600 | J40: =C40*F40 -> 641550 | K40: =C40*G40 -> 830272.5 | L40: =C40*H40 -> 6365422.5 | N40: Harga acuan | O40: Standar
A41: VIII.3 | B41: Pintu KM PVC | C41: =AHSP!$K$425 -> 1 | D41: unit | E41: =AHSP!$G$432 -> 949900 | F41: =AHSP!$G$429 -> 213850 | G41: =AHSP!$G$434 -> 174562.5 | H41: =SUM(E41:G41) -> 1338312.5 | I41: =C41*E41 -> 949900 | J41: =C41*F41 -> 213850 | K41: =C41*G41 -> 174562.5 | L41: =C41*H41 -> 1338312.5 | N41: Harga acuan | O41: Standar
...

Sheet Kontrol Harga
A1: KONTROL HARGA PER m² — pekerjaan standar
A2: Harga per m² hanya menghitung pekerjaan standar bangunan utama, sama seperti cara kontraktor menawarkan 'harga per meter'. Pekerjaan tambahan, ongkos kirim, dana cadangan, dan pajak tidak ikut.
A4: Rentang harga pasar borongan (bahan + upah) per m² — Jabodetabek 2026 | B4: Minimum | C4: Maksimum | D4: Dasar penetapan
A5: Sederhana | B5: 3500000 | C5: 5000000 | D5: Median batas bawah & atas dari 10 artikel kontraktor/portal properti 2026: sobatbangun, tokban, superkos, PropNex, Akbar Konstruksi, Tricipta Karya, Dinasti Arsitek, caribisnis, indohomesarana (Jabodetabek), asiaarsitek
A6: Menengah | B6: 5000000 | C6: 7000000 | D6: Median batas bawah & atas dari 10 artikel kontraktor/portal properti 2026: sobatbangun, tokban, superkos, PropNex, Akbar Konstruksi, Tricipta Karya, Dinasti Arsitek, caribisnis, indohomesarana (Jabodetabek), asiaarsitek
A7: Mewah | B7: 7000000 | C7: 10000000 | D7: Median batas bawah & atas dari 10 artikel kontraktor/portal properti 2026: sobatbangun, tokban, superkos, PropNex, Akbar Konstruksi, Tricipta Karya, Dinasti Arsitek, caribisnis, indohomesarana (Jabodetabek), asiaarsitek
A8: Borongan jasa (upah + keuntungan mandor) per m² — semua kelas | B8: 1000000 | C8: 1800000 | D8: Median dari 5 kisaran 2026: caribisnis, indohomesarana, sobatbangun, asiaarsitek (1 lantai & 2 lantai)
A9: Rentang dari artikel pasar (bukan data resmi) — dipakai sebagai rambu, bukan patokan pasti. Untuk luar Jabodetabek kalikan dengan faktor IKK daerah.
A11: Pemeriksaan | B11: Nilai per m² | C11: Rentang wajar | D11: Status
A12: Borongan — harga per m² pekerjaan standar | B12: =SUMIF('RAB Borongan'!$O$6:$O$71,"Standar",'RAB Borongan'!$L$6:$L$71)/Volume!$B$23 -> 5342826.5 | C12: =TEXT(VLOOKUP(Parameter!$B$15,'Kontrol Harga'!$A$5:$C$7,2,FALSE()),"#,##0")&" – "&TEXT(VLOOKUP(Parameter!$B$15,'Kontrol Harga'!$A$5:$C$7,3,FALSE()),"#,##0") -> 5,000,000 – 7,000,000 | D12: =IF(B12<VLOOKUP(Parameter!$B$15,'Kontrol Harga'!$A$5:$C$7,2,FALSE()),"Di bawah rentang ("&TEXT(B12/(VLOOKUP(Parameter!$B$15,'Kontrol Harga'!$A$5:$C$7,2,FALSE()))-1,"0%")&") — periksa apakah ada pekerjaan/spesifikasi yang terlewat",IF(B12>VLOOKUP(Parameter!$B$15,'Kontrol Harga'!$A$5:$C$7,3,FALSE()),"Di atas rentang (+"&TEXT(B12/(VLOOKUP(Parameter!$B$15,'Kontrol Harga'!$A$5:$C$7,3,FALSE()))-1,"0%")&") — periksa spesifikasi atau harga yang terlalu tinggi","Dalam rentang pasar")) -> Dalam rentang pasar
A13: Swakelola — biaya per m² pekerjaan standar | B13: =SUMIF('RAB Swakelola'!$M$6:$M$71,"Standar",'RAB Swakelola'!$J$6:$J$71)/Volume!$B$23 -> 4645936.1 | C13: =TEXT(VLOOKUP(Parameter!$B$15,'Kontrol Harga'!$A$5:$C$7,2,FALSE())/(1+Parameter!$B$4),"#,##0")&" – "&TEXT(VLOOKUP(Parameter!$B$15,'Kontrol Harga'!$A$5:$C$7,3,FALSE())/(1+Parameter!$B$4),"#,##0") -> 4,347,826 – 6,086,957 | D13: =IF(B13<VLOOKUP(Parameter!$B$15,'Kontrol Harga'!$A$5:$C$7,2,FALSE())/(1+Parameter!$B$4),"Di bawah rentang ("&TEXT(B13/(VLOOKUP(Parameter!$B$15,'Kontrol Harga'!$A$5:$C$7,2,FALSE())/(1+Parameter!$B$4))-1,"0%")&") — periksa apakah ada pekerjaan/spesifikasi yang terlewat",IF(B13>VLOOKUP(Parameter!$B$15,'Kontrol Harga'!$A$5:$C$7,3,FALSE())/(1+Parameter!$B$4),"Di atas rentang (+"&TEXT(B13/(VLOOKUP(Parameter!$B$15,'Kontrol Harga'!$A$5:$C$7,3,FALSE())/(1+Parameter!$B$4))-1,"0%")&") — periksa spesifikasi atau harga yang terlalu tinggi","Dalam rentang pasar")) -> Dalam rentang pasar
A14: Upah per m² pekerjaan standar + margin (setara borongan jasa) | B14: =SUMIF('RAB Borongan'!$O$6:$O$71,"Standar",'RAB Borongan'!$J$6:$J$71)*(1+Parameter!$B$4)/Volume!$B$23 -> 1678954.1 | C14: =TEXT('Kontrol Harga'!$B$8,"#,##0")&" – "&TEXT('Kontrol Harga'!$C$8,"#,##0") -> 1,000,000 – 1,800,000 | D14: =IF(B14<'Kontrol Harga'!$B$8,"Di bawah rentang ("&TEXT(B14/('Kontrol Harga'!$B$8)-1,"0%")&") — periksa apakah ada pekerjaan/spesifikasi yang terlewat",IF(B14>'Kontrol Harga'!$C$8,"Di atas rentang (+"&TEXT(B14/('Kontrol Harga'!$C$8)-1,"0%")&") — periksa spesifikasi atau harga yang terlalu tinggi","Dalam rentang pasar")) -> Dalam rentang pasar
A15: ="Luas bangunan: "&TEXT(Volume!$B$23,"0")&" m² · Paket: "&Parameter!$B$15 -> Luas bangunan: 36 m² · Paket: Menengah
A17: Masuk hitungan per m² (Standar) | D17: Tidak masuk hitungan per m² (Tambahan & biaya lain)
A18: ✓ Persiapan (bouwplank, pembersihan, air & listrik kerja) | D18: ✗ Toren air, pompa air, shower set
A19: ✓ Tanah & pondasi | D19: ✗ Dapur (meja dapur/kitchen set)
A20: ✓ Struktur beton | D20: ✗ Carport, kanopi, pagar & pintu pagar
A21: ✓ Dinding, plester, acian | D21: ✗ Ongkos kirim bahan (swakelola)
A22: ✓ Atap | D22: ✗ Dana cadangan
A23: ✓ Plafon | D23: ✗ Pajak (PPN / PPN KMS)
A24: ✓ Lantai & keramik | D24: ✗ Tanah, PBG/IMB, notaris, desain
A25: ✓ Pintu & jendela | D25: ✗ Sambungan PLN/PDAM permanen
A26: ✓ Cat | D26: ✗ Taman, interior, furnitur, AC
A27: ✓ Sanitair & plumbing (kloset, wastafel, floor drain, kran, pipa, septictank)
A28: ✓ Instalasi listrik
A30: Sumber cakupan: asiaarsitek.com, indohomesarana.com, propnexplus.com, semenmerahputih.com (2026) — harga per meter umumnya hanya bangunan utama; pagar, carport, kanopi, taman, kitchen set, interior, PBG, dan sambungan PLN/PDAM dihitung terpisah.

Sheet Perhitungan Bahan
A1: PERHITUNGAN BAHAN — kebutuhan, jumlah beli, dan biaya
A2: Kebutuhan = volume × koefisien AHSP (sudah termasuk susut). Biaya dihitung dari kebutuhan; jumlah beli (kemasan) hanya panduan belanja. Ubah harga per kemasan (biru) sesuai toko Anda.
A4: Kode | B4: Bahan | C4: Spesifikasi | D4: Kebutuhan | E4: Satuan | F4: Kemasan beli | G4: Isi / kemasan | H4: Jumlah beli | I4: Harga / kemasan | J4: Harga / satuan | K4: BIAYA | L4: Link toko online | M4: Asal harga | N4: Referensi | O4: Curah? | P4: Catatan
A5: SMN | B5: Semen PCC | C5: Tiga Roda / Gresik | D5: =SUMIFS(AHSP!$L$5:$L$3000,AHSP!$C$5:$C$3000,A5,AHSP!$J$5:$J$3000,"Bahan") -> 6784.1057 | E5: kg | F5: zak 40 kg | G5: 40 | H5: =MAX(0,ROUNDUP(D5/G5-0.0001,0)) -> 170 | I5: 63000 | J5: =I5/G5 -> 1575 | K5: =D5*J5 -> 10684966 | L5: — | M5: Triangulasi: SSH Badung 2026, RAB profesional (bangun.com), toko | N5: Harga acuan | O5: Tidak | P5: ="atau "&ROUNDUP(D5/50,0)&" zak 50 kg" -> atau 136 zak 50 kg
A6: PSP | B6: Pasir pasang | D6: =SUMIFS(AHSP!$L$5:$L$3000,AHSP!$C$5:$C$3000,A6,AHSP!$J$5:$J$3000,"Bahan") -> 13.67734 | E6: m³ | F6: m³ | G6: 1 | H6: =MAX(0,ROUNDUP(D6/G6-0.0001,0)) -> 14 | I6: 295200 | J6: =I6/G6 -> 295200 | K6: =D6*J6 -> 4037550.7 | L6: — | M6: SSH Badung 2026 & RAB profesional (bangun.com) | N6: Harga acuan | O6: Ya | P6: ="≈ "&ROUND(D6/6.75,1)&" truk colt diesel" -> ≈ 2 truk colt diesel
A7: PSB | B7: Pasir beton | D7: =SUMIFS(AHSP!$L$5:$L$3000,AHSP!$C$5:$C$3000,A7,AHSP!$J$5:$J$3000,"Bahan") -> 4.0063018 | E7: m³ | F7: m³ | G7: 1 | H7: =MAX(0,ROUNDUP(D7/G7-0.0001,0)) -> 5 | I7: 379000 | J7: =I7/G7 -> 379000 | K7: =D7*J7 -> 1518388.4 | L7: — | M7: RAB profesional — bangun.com | N7: Harga acuan | O7: Ya
A8: SPL | B8: Batu split 1–2 cm | D8: =SUMIFS(AHSP!$L$5:$L$3000,AHSP!$C$5:$C$3000,A8,AHSP!$J$5:$J$3000,"Bahan") -> 5.6368048 | E8: m³ | F8: m³ | G8: 1 | H8: =MAX(0,ROUNDUP(D8/G8-0.0001,0)) -> 6 | I8: 385900 | J8: =I8/G8 -> 385900 | K8: =D8*J8 -> 2175243 | L8: — | M8: SSH Kab. Badung 2026 | N8: Harga acuan | O8: Ya
A9: PSU | B9: Pasir urug | D9: =SUMIFS(AHSP!$L$5:$L$3000,AHSP!$C$5:$C$3000,A9,AHSP!$J$5:$J$3000,"Bahan") -> 7.473 | E9: m³ | F9: m³ | G9: 1 | H9: =MAX(0,ROUNDUP(D9/G9-0.0001,0)) -> 8 | I9: 209000 | J9: =I9/G9 -> 209000 | K9: =D9*J9 -> 1561857 | L9: — | M9: SSH Badung & RAB profesional (bangun.com) | N9: Harga acuan | O9: Ya
A10: BTK | B10: Batu kali belah | D10: =SUMIFS(AHSP!$L$5:$L$3000,AHSP!$C$5:$C$3000,A10,AHSP!$J$5:$J$3000,"Bahan") -> 12.42 | E10: m³ | F10: m³ | G10: 1 | H10: =MAX(0,ROUNDUP(D10/G10-0.0001,0)) -> 13 | I10: 343200 | J10: =I10/G10 -> 343200 | K10: =D10*J10 -> 4262544 | L10: — | M10: SSH Badung & RAB profesional (bangun.com) | N10: Harga acuan | O10: Ya
A11: D10 | B11: Besi ulir D10 full SNI | C11: 12 m | D11: =SUMIFS(AHSP!$L$5:$L$3000,AHSP!$C$5:$C$3000,A11,AHSP!$J$5:$J$3000,"Bahan") -> 291.61044 | E11: kg | F11: batang | G11: 7.4 | H11: =MAX(0,ROUNDUP(D11/G11-0.0001,0)) -> 40 | I11: 85500 | J11: =I11/G11 -> 11554.054 | K11: =D11*J11 -> 3369282.8 | L11: — | M11: Toko online, SSH Badung, RAB profesional (bangun.com) | N11: Harga acuan | O11: Tidak
A12: D8 | B12: Besi D8 full SNI | C12: 12 m | D12: =SUMIFS(AHSP!$L$5:$L$3000,AHSP!$C$5:$C$3000,A12,AHSP!$J$5:$J$3000,"Bahan") -> 108.88798 | E12: kg | F12: batang | G12: 4.74 | H12: =MAX(0,ROUNDUP(D12/G12-0.0001,0)) -> 23 | I12: 53800 | J12: =I12/G12 -> 11350.211 | K12: =D12*J12 -> 1235901.5 | L12: — | M12: Toko, SSH Badung, RAB profesional (bangun.com) | N12: Harga acuan | O12: Tidak
A13: D6 | B13: Besi polos Ø6 | C13: 12 m, sengkang | D13: =SUMIFS(AHSP!$L$5:$L$3000,AHSP!$C$5:$C$3000,A13,AHSP!$J$5:$J$3000,"Bahan") -> 109.54038 | E13: kg | F13: batang | G13: 2.66 | H13: =MAX(0,ROUNDUP(D13/G13-0.0001,0)) -> 42 | I13: 30100 | J13: =I13/G13 -> 11315.789 | K13: =D13*J13 -> 1239535.9 | L13: — | M13: Turunan harga besi per kg | N13: Harga acuan | O13: Tidak
A14: KWT | B14: Kawat bendrat | D14: =SUMIFS(AHSP!$L$5:$L$3000,AHSP!$C$5:$C$3000,A14,AHSP!$J$5:$J$3000,"Bahan") -> 6.9663246 | E14: kg | F14: kg | G14: 1 | H14: =MAX(0,ROUNDUP(D14/G14-0.0001,0)) -> 7 | I14: 26200 | J14: =I14/G14 -> 26200 | K14: =D14*J14 -> 182517.7 | L14: — | M14: RAB profesional — bangun.com | N14: Harga acuan | O14: Tidak
A15: MPX | B15: Multipleks 9 mm | C15: 122×244, bekisting (pakai ulang 4×) | D15: =SUMIFS(AHSP!$L$5:$L$3000,AHSP!$C$5:$C$3000,A15,AHSP!$J$5:$J$3000,"Bahan") -> 3.764914 | E15: lembar | F15: lembar | G15: 1 | H15: =MAX(0,ROUNDUP(D15/G15-0.0001,0)) -> 4 | I15: 214200 | J15: =I15/G15 -> 214200 | K15: =D15*J15 -> 806444.58 | L15: — | M15: RAB profesional — bangun.com | N15: Harga acuan | O15: Tidak
A16: KSO | B16: Kayu kaso 5/7 | C16: 4 m, bekisting | D16: =SUMIFS(AHSP!$L$5:$L$3000,AHSP!$C$5:$C$3000,A16,AHSP!$J$5:$J$3000,"Bahan") -> 42.259242 | E16: batang | F16: batang | G16: 1 | H16: =MAX(0,ROUNDUP(D16/G16-0.0001,0)) -> 43 | I16: 38000 | J16: =I16/G16 -> 38000 | K16: =D16*J16 -> 1605851.2 | L16: — | M16: Estimasi — belum ada sumber | N16: Estimasi | O16: Tidak
A17: PKU | B17: Paku 5–10 cm | D17: =SUMIFS(AHSP!$L$5:$L$3000,AHSP!$C$5:$C$3000,A17,AHSP!$J$5:$J$3000,"Bahan") -> 4.3027589 | E17: kg | F17: kg | G17: 1 | H17: =MAX(0,ROUNDUP(D17/G17-0.0001,0)) -> 5 | I17: 24200 | J17: =I17/G17 -> 24200 | K17: =D17*J17 -> 104126.76 | L17: — | M17: RAB profesional — bangun.com | N17: Harga acuan | O17: Tidak
A18: MYK | B18: Minyak bekisting | D18: =SUMIFS(AHSP!$L$5:$L$3000,AHSP!$C$5:$C$3000,A18,AHSP!$J$5:$J$3000,"Bahan") -> 2.1513794 | E18: liter | F18: liter | G18: 1 | H18: =MAX(0,ROUNDUP(D18/G18-0.0001,0)) -> 3 | I18: 26400 | J18: =I18/G18 -> 26400 | K18: =D18*J18 -> 56796.417 | L18: — | M18: SSH Badung & RAB profesional (bangun.com) | N18: Harga acuan | O18: Tidak
A19: BRG | B19: Bata ringan 10 cm | C19: 60×20×10 (±83 buah/m³) | D19: =SUMIFS(AHSP!$L$5:$L$3000,AHSP!$C$5:$C$3000,A19,AHSP!$J$5:$J$3000,"Bahan") -> 988.32783 | E19: buah | F19: buah | G19: 1 | H19: =MAX(0,ROUNDUP(D19/G19-0.0001,0)) -> 989 | I19: 9820 | J19: =I19/G19 -> 9820 | K19: =D19*J19 -> 9705379.3 | L19: — | M19: SSH Badung, RAB profesional (bangun.com), toko | N19: Harga acuan | O19: Tidak | P19: ="≈ "&ROUND(D19/83,1)&" m³" -> ≈ 11.9 m³
A20: MRT | B20: Mortar instan bata ringan | D20: =SUMIFS(AHSP!$L$5:$L$3000,AHSP!$C$5:$C$3000,A20,AHSP!$J$5:$J$3000,"Bahan") -> 867.05565 | E20: kg | F20: zak 40 kg | G20: 40 | H20: =MAX(0,ROUNDUP(D20/G20-0.0001,0)) -> 22 | I20: 87000 | J20: =I20/G20 -> 2175 | K20: =D20*J20 -> 1885846 | L20: — | M20: detikProperti Mei 2025 (Global Union) | N20: Harga acuan | O20: Tidak
A21: GNT | B21: Genteng beton | C21: ±10 buah/m² | D21: =SUMIFS(AHSP!$L$5:$L$3000,AHSP!$C$5:$C$3000,A21,AHSP!$J$5:$J$3000,"Bahan") -> 616.55466 | E21: buah | F21: buah | G21: 1 | H21: =MAX(0,ROUNDUP(D21/G21-0.0001,0)) -> 617 | I21: 12450 | J21: =I21/G21 -> 12450 | K21: =D21*J21 -> 7676105.5 | L21: — | M21: SSH Kab. Badung 2026 | N21: Harga acuan | O21: Tidak
A22: NOK | B22: Nok genteng beton | D22: =SUMIFS(AHSP!$L$5:$L$3000,AHSP!$C$5:$C$3000,A22,AHSP!$J$5:$J$3000,"Bahan") -> 22.68 | E22: buah | F22: buah | G22: 1 | H22: =MAX(0,ROUNDUP(D22/G22-0.0001,0)) -> 23 | I22: 8350 | J22: =I22/G22 -> 8350 | K22: =D22*J22 -> 189378 | L22: — | M22: SSH Kab. Badung 2026 | N22: Harga acuan | O22: Tidak
A23: GYP | B23: Papan gypsum 9 mm | C23: 120×240 (2,88 m²) | D23: =SUMIFS(AHSP!$L$5:$L$3000,AHSP!$C$5:$C$3000,A23,AHSP!$J$5:$J$3000,"Bahan") -> 15.46857 | E23: lembar | F23: lembar | G23: 1 | H23: =MAX(0,ROUNDUP(D23/G23-0.0001,0)) -> 16 | I23: 81500 | J23: =I23/G23 -> 81500 | K23: =D23*J23 -> 1260688.5 | L23: — | M23: RAB profesional — bangun.com | N23: Harga acuan | O23: Tidak
A24: HLW | B24: Hollow galvalum plafon 4×4 / 2×4 | C24: 4 m | D24: =SUMIFS(AHSP!$L$5:$L$3000,AHSP!$C$5:$C$3000,A24,AHSP!$J$5:$J$3000,"Bahan") -> 31.89375 | E24: batang | F24: batang | G24: 1 | H24: =MAX(0,ROUNDUP(D24/G24-0.0001,0)) -> 32 | I24: 25000 | J24: =I24/G24 -> 25000 | K24: =D24*J24 -> 797343.75 | L24: — | M24: Estimasi — belum ada sumber | N24: Estimasi | O24: Tidak
A25: CMP | B25: Compound & sekrup gypsum | D25: =SUMIFS(AHSP!$L$5:$L$3000,AHSP!$C$5:$C$3000,A25,AHSP!$J$5:$J$3000,"Bahan") -> 14.88375 | E25: kg | F25: sak 20 kg | G25: 20 | H25: =MAX(0,ROUNDUP(D25/G25-0.0001,0)) -> 1 | I25: 85000 | J25: =I25/G25 -> 4250 | K25: =D25*J25 -> 63255.938 | L25: — | M25: Estimasi — belum ada sumber | N25: Estimasi | O25: Tidak
A26: GRN | B26: Granit HT 60×60 | C26: KW1, 4 keping/dus | D26: =SUMIFS(AHSP!$L$5:$L$3000,AHSP!$C$5:$C$3000,A26,AHSP!$J$5:$J$3000,"Bahan") -> 37.4325 | E26: m² | F26: dus | G26: 1.44 | H26: =MAX(0,ROUNDUP(D26/G26-0.0001,0)) -> 26 | I26: 195000 | J26: =I26/G26 -> 135416.67 | K26: =D26*J26 -> 5068984.4 | L26: buka toko | M26: Median 3 toko Jabodetabek (Tokopedia) | N26: Harga acuan | O26: Tidak
A27: KKM | B27: Keramik lantai KM anti-slip 25×25 | D27: =SUMIFS(AHSP!$L$5:$L$3000,AHSP!$C$5:$C$3000,A27,AHSP!$J$5:$J$3000,"Bahan") -> 3.3 | E27: m² | F27: dus (±1 m²) | G27: 1 | H27: =MAX(0,ROUNDUP(D27/G27-0.0001,0)) -> 4 | I27: 85000 | J27: =I27/G27 -> 85000 | K27: =D27*J27 -> 280500 | L27: — | M27: Estimasi — belum ada sumber | N27: Estimasi | O27: Tidak
A28: KDW | B28: Keramik dinding KM 25×40 | D28: =SUMIFS(AHSP!$L$5:$L$3000,AHSP!$C$5:$C$3000,A28,AHSP!$J$5:$J$3000,"Bahan") -> 16.94 | E28: m² | F28: dus (±1 m²) | G28: 1 | H28: =MAX(0,ROUNDUP(D28/G28-0.0001,0)) -> 17 | I28: 70000 | J28: =I28/G28 -> 70000 | K28: =D28*J28 -> 1185800 | L28: buka toko | M28: Toko Kab. Bogor (Tokopedia) | N28: Harga acuan | O28: Tidak
A29: KTR | B29: Keramik teras 40×40 | C29: 6 keping/dus | D29: =SUMIFS(AHSP!$L$5:$L$3000,AHSP!$C$5:$C$3000,A29,AHSP!$J$5:$J$3000,"Bahan") -> 4.95 | E29: m² | F29: dus | G29: 0.96 | H29: =MAX(0,ROUNDUP(D29/G29-0.0001,0)) -> 6 | I29: 60000 | J29: =I29/G29 -> 62500 | K29: =D29*J29 -> 309375 | L29: buka toko | M29: Toko Kab. Bogor (Tokopedia) | N29: Harga acuan | O29: Tidak
A30: NAT | B30: Semen warna / nat | D30: =SUMIFS(AHSP!$L$5:$L$3000,AHSP!$C$5:$C$3000,A30,AHSP!$J$5:$J$3000,"Bahan") -> 24.865 | E30: kg | F30: bungkus 1 kg | G30: 1 | H30: =MAX(0,ROUNDUP(D30/G30-0.0001,0)) -> 25 | I30: 15000 | J30: =I30/G30 -> 15000 | K30: =D30*J30 -> 372975 | L30: — | M30: Estimasi — belum ada sumber | N30: Estimasi | O30: Tidak
A31: PLM | B31: Plamir tembok | D31: =SUMIFS(AHSP!$L$5:$L$3000,AHSP!$C$5:$C$3000,A31,AHSP!$J$5:$J$3000,"Bahan") -> 17.421915 | E31: kg | F31: galon 5 kg | G31: 5 | H31: =MAX(0,ROUNDUP(D31/G31-0.0001,0)) -> 4 | I31: 150000 | J31: =I31/G31 -> 30000 | K31: =D31*J31 -> 522657.45 | L31: — | M31: Estimasi — belum ada sumber | N31: Estimasi | O31: Tidak
A32: CDI | B32: Cat dasar interior | D32: =SUMIFS(AHSP!$L$5:$L$3000,AHSP!$C$5:$C$3000,A32,AHSP!$J$5:$J$3000,"Bahan") -> 17.421915 | E32: kg | F32: galon 5 kg | G32: 5 | H32: =MAX(0,ROUNDUP(D32/G32-0.0001,0)) -> 4 | I32: 200000 | J32: =I32/G32 -> 40000 | K32: =D32*J32 -> 696876.6 | L32: — | M32: Estimasi — belum ada sumber | N32: Estimasi | O32: Tidak
A33: CTL | B33: Cat Catylac interior | D33: =SUMIFS(AHSP!$L$5:$L$3000,AHSP!$C$5:$C$3000,A33,AHSP!$J$5:$J$3000,"Bahan") -> 45.296979 | E33: kg | F33: galon 5 kg | G33: 5 | H33: =MAX(0,ROUNDUP(D33/G33-0.0001,0)) -> 10 | I33: 224000 | J33: =I33/G33 -> 44800 | K33: =D33*J33 -> 2029304.7 | L33: buka toko | M33: Median 3 toko (Tokopedia) | N33: Harga acuan | O33: Tidak
A34: CDE | B34: Cat dasar eksterior | D34: =SUMIFS(AHSP!$L$5:$L$3000,AHSP!$C$5:$C$3000,A34,AHSP!$J$5:$J$3000,"Bahan") -> 8.860877 | E34: kg | F34: galon 4 kg | G34: 4 | H34: =MAX(0,ROUNDUP(D34/G34-0.0001,0)) -> 3 | I34: 347500 | J34: =I34/G34 -> 86875 | K34: =D34*J34 -> 769788.69 | L34: buka toko | M34: Toko Depok (Tokopedia) | N34: Harga acuan | O34: Tidak
A35: WSH | B35: Dulux Weathershield | C35: eksterior | D35: =SUMIFS(AHSP!$L$5:$L$3000,AHSP!$C$5:$C$3000,A35,AHSP!$J$5:$J$3000,"Bahan") -> 17.065205 | E35: liter | F35: galon 2,5 L | G35: 2.5 | H35: =MAX(0,ROUNDUP(D35/G35-0.0001,0)) -> 7 | I35: 490720 | J35: =I35/G35 -> 196288 | K35: =D35*J35 -> 3349695 | L35: buka toko | M35: Median 3 toko (Tokopedia) | N35: Harga acuan | O35: Tidak
A36: PAW | B36: Pipa PVC AW ½" | C36: 4 m | D36: =SUMIFS(AHSP!$L$5:$L$3000,AHSP!$C$5:$C$3000,A36,AHSP!$J$5:$J$3000,"Bahan") -> 27.5 | E36: m | F36: batang | G36: 4 | H36: =MAX(0,ROUNDUP(D36/G36-0.0001,0)) -> 7 | I36: 38000 | J36: =I36/G36 -> 9500 | K36: =D36*J36 -> 261250 | L36: — | M36: Estimasi — belum ada sumber | N36: Estimasi | O36: Tidak
A37: PD3 | B37: Pipa PVC D 3" | C37: 4 m | D37: =SUMIFS(AHSP!$L$5:$L$3000,AHSP!$C$5:$C$3000,A37,AHSP!$J$5:$J$3000,"Bahan") -> 11 | E37: m | F37: batang | G37: 4 | H37: =MAX(0,ROUNDUP(D37/G37-0.0001,0)) -> 3 | I37: 160000 | J37: =I37/G37 -> 40000 | K37: =D37*J37 -> 440000 | L37: — | M37: Estimasi — belum ada sumber | N37: Estimasi | O37: Tidak
A38: PD4 | B38: Pipa PVC D 4" | C38: 4 m | D38: =SUMIFS(AHSP!$L$5:$L$3000,AHSP!$C$5:$C$3000,A38,AHSP!$J$5:$J$3000,"Bahan") -> 8.8 | E38: m | F38: batang | G38: 4 | H38: =MAX(0,ROUNDUP(D38/G38-0.0001,0)) -> 3 | I38: 230000 | J38: =I38/G38 -> 57500 | K38: =D38*J38 -> 506000 | L38: — | M38: Estimasi — belum ada sumber | N38: Estimasi | O38: Tidak
A39: FTP | B39: Fitting, lem & klem pipa | C39: per meter pipa | D39: =SUMIFS(AHSP!$L$5:$L$3000,AHSP!$C$5:$C$3000,A39,AHSP!$J$5:$J$3000,"Bahan") -> 43 | E39: m | F39: paket per m | G39: 1 | H39: =MAX(0,ROUNDUP(D39/G39-0.0001,0)) -> 43 | I39: 7500 | J39: =I39/G39 -> 7500 | K39: =D39*J39 -> 322500 | L39: — | M39: Estimasi — belum ada sumber | N39: Estimasi | O39: Tidak
A40: K15 | B40: Kabel NYM 2×1,5 mm² | D40: =SUMIFS(AHSP!$L$5:$L$3000,AHSP!$C$5:$C$3000,A40,AHSP!$J$5:$J$3000,"Bahan") -> 126.5 | E40: m | F40: roll 50 m | G40: 50 | H40: =MAX(0,ROUNDUP(D40/G40-0.0001,0)) -> 3 | I40: 575000 | J40: =I40/G40 -> 11500 | K40: =D40*J40 -> 1454750 | L40: — | M40: Estimasi — belum ada sumber | N40: Estimasi | O40: Tidak
A41: K25 | B41: Kabel NYM 3×2,5 mm² | D41: =SUMIFS(AHSP!$L$5:$L$3000,AHSP!$C$5:$C$3000,A41,AHSP!$J$5:$J$3000,"Bahan") -> 77 | E41: m | F41: roll 50 m | G41: 50 | H41: =MAX(0,ROUNDUP(D41/G41-0.0001,0)) -> 2 | I41: 1350000 | J41: =I41/G41 -> 27000 | K41: =D41*J41 -> 2079000 | L41: — | M41: SSH Badung & RAB profesional (bangun.com) | N41: Harga acuan | O41: Tidak
...

Sheet Perhitungan Upah
A1: PERHITUNGAN UPAH TUKANG
A2: Isi upah harian sesuai tarif di lokasi Anda (sel kuning). Kebutuhan tenaga dihitung otomatis dari volume × koefisien AHSP; upah = kebutuhan × upah per hari.
A4: Jenis tenaga | B4: Kode | C4: Upah per hari | D4: Keterangan
A5: Pekerja | B5: PKJ | C5: 130500 | D5: Acuan DKI 2026
A6: Tukang batu | B6: TKG | C6: 175300 | D6: Acuan DKI 2026
A7: Tukang kayu | B7: TKY | C7: 174700 | D7: Acuan DKI 2026
A8: Tukang besi | B8: TBS | C8: 174700 | D8: Acuan DKI 2026
A9: Tukang cat | B9: TCT | C9: 165000 | D9: Acuan DKI 2026
A10: Tukang listrik | B10: TLS | C10: 182800 | D10: Acuan DKI 2026
A11: Tukang pipa | B11: TPP | C11: 184400 | D11: Acuan DKI 2026
A12: Kepala tukang | B12: KTK | C12: 198900 | D12: Acuan DKI 2026
A13: Mandor | B13: MDR | C13: 228300 | D13: Acuan DKI 2026
A14: Sumber acuan: triangulasi harga pasar Jakarta, RAB kontraktor profesional (Indeks Biaya Bangun, bangun.com), dan standar upah resmi.
A16: KEBUTUHAN TENAGA & UPAH PER TAHAP
A17: Kebutuhan (orang-hari) = volume × koefisien AHSP. Upah = kebutuhan × upah per hari. Angka ini sama untuk swakelola dan borongan.
A18: Tahap / jenis tenaga | B18: Kode | C18: Kebutuhan (orang-hari) | D18: Upah per hari | E18: UPAH
A19: I. PERSIAPAN | C19: =SUM(C20:C28) -> 18.6 | E19: =SUM(E20:E28) -> 2506860
A20: Pekerja | B20: PKJ | C20: =SUMIFS(AHSP!$L$5:$L$3000,AHSP!$I$5:$I$3000,"I",AHSP!$C$5:$C$3000,B20,AHSP!$J$5:$J$3000,"Upah") -> 16.8 | D20: =INDEX('Perhitungan Upah'!$C$5:$C$13,MATCH(B20,'Perhitungan Upah'!$B$5:$B$13,0)) -> 130500 | E20: =C20*D20 -> 2192400
A21: Tukang batu | B21: TKG | C21: =SUMIFS(AHSP!$L$5:$L$3000,AHSP!$I$5:$I$3000,"I",AHSP!$C$5:$C$3000,B21,AHSP!$J$5:$J$3000,"Upah") -> 0 | D21: =INDEX('Perhitungan Upah'!$C$5:$C$13,MATCH(B21,'Perhitungan Upah'!$B$5:$B$13,0)) -> 175300 | E21: =C21*D21 -> 0
A22: Tukang kayu | B22: TKY | C22: =SUMIFS(AHSP!$L$5:$L$3000,AHSP!$I$5:$I$3000,"I",AHSP!$C$5:$C$3000,B22,AHSP!$J$5:$J$3000,"Upah") -> 1.8 | D22: =INDEX('Perhitungan Upah'!$C$5:$C$13,MATCH(B22,'Perhitungan Upah'!$B$5:$B$13,0)) -> 174700 | E22: =C22*D22 -> 314460
A23: Tukang besi | B23: TBS | C23: =SUMIFS(AHSP!$L$5:$L$3000,AHSP!$I$5:$I$3000,"I",AHSP!$C$5:$C$3000,B23,AHSP!$J$5:$J$3000,"Upah") -> 0 | D23: =INDEX('Perhitungan Upah'!$C$5:$C$13,MATCH(B23,'Perhitungan Upah'!$B$5:$B$13,0)) -> 174700 | E23: =C23*D23 -> 0
A24: Tukang cat | B24: TCT | C24: =SUMIFS(AHSP!$L$5:$L$3000,AHSP!$I$5:$I$3000,"I",AHSP!$C$5:$C$3000,B24,AHSP!$J$5:$J$3000,"Upah") -> 0 | D24: =INDEX('Perhitungan Upah'!$C$5:$C$13,MATCH(B24,'Perhitungan Upah'!$B$5:$B$13,0)) -> 165000 | E24: =C24*D24 -> 0
A25: Tukang listrik | B25: TLS | C25: =SUMIFS(AHSP!$L$5:$L$3000,AHSP!$I$5:$I$3000,"I",AHSP!$C$5:$C$3000,B25,AHSP!$J$5:$J$3000,"Upah") -> 0 | D25: =INDEX('Perhitungan Upah'!$C$5:$C$13,MATCH(B25,'Perhitungan Upah'!$B$5:$B$13,0)) -> 182800 | E25: =C25*D25 -> 0
A26: Tukang pipa | B26: TPP | C26: =SUMIFS(AHSP!$L$5:$L$3000,AHSP!$I$5:$I$3000,"I",AHSP!$C$5:$C$3000,B26,AHSP!$J$5:$J$3000,"Upah") -> 0 | D26: =INDEX('Perhitungan Upah'!$C$5:$C$13,MATCH(B26,'Perhitungan Upah'!$B$5:$B$13,0)) -> 184400 | E26: =C26*D26 -> 0
A27: Kepala tukang | B27: KTK | C27: =SUMIFS(AHSP!$L$5:$L$3000,AHSP!$I$5:$I$3000,"I",AHSP!$C$5:$C$3000,B27,AHSP!$J$5:$J$3000,"Upah") -> 0 | D27: =INDEX('Perhitungan Upah'!$C$5:$C$13,MATCH(B27,'Perhitungan Upah'!$B$5:$B$13,0)) -> 198900 | E27: =C27*D27 -> 0
A28: Mandor | B28: MDR | C28: =SUMIFS(AHSP!$L$5:$L$3000,AHSP!$I$5:$I$3000,"I",AHSP!$C$5:$C$3000,B28,AHSP!$J$5:$J$3000,"Upah") -> 0 | D28: =INDEX('Perhitungan Upah'!$C$5:$C$13,MATCH(B28,'Perhitungan Upah'!$B$5:$B$13,0)) -> 228300 | E28: =C28*D28 -> 0
A29: II. TANAH & PONDASI | C29: =SUM(C30:C38) -> 39.774065 | E29: =SUM(E30:E38) -> 5569054.4
A30: Pekerja | B30: PKJ | C30: =SUMIFS(AHSP!$L$5:$L$3000,AHSP!$I$5:$I$3000,"II",AHSP!$C$5:$C$3000,B30,AHSP!$J$5:$J$3000,"Upah") -> 33.095981 | D30: =INDEX('Perhitungan Upah'!$C$5:$C$13,MATCH(B30,'Perhitungan Upah'!$B$5:$B$13,0)) -> 130500 | E30: =C30*D30 -> 4319025.6
A31: Tukang batu | B31: TKG | C31: =SUMIFS(AHSP!$L$5:$L$3000,AHSP!$I$5:$I$3000,"II",AHSP!$C$5:$C$3000,B31,AHSP!$J$5:$J$3000,"Upah") -> 4.908195 | D31: =INDEX('Perhitungan Upah'!$C$5:$C$13,MATCH(B31,'Perhitungan Upah'!$B$5:$B$13,0)) -> 175300 | E31: =C31*D31 -> 860406.58
A32: Tukang kayu | B32: TKY | C32: =SUMIFS(AHSP!$L$5:$L$3000,AHSP!$I$5:$I$3000,"II",AHSP!$C$5:$C$3000,B32,AHSP!$J$5:$J$3000,"Upah") -> 0 | D32: =INDEX('Perhitungan Upah'!$C$5:$C$13,MATCH(B32,'Perhitungan Upah'!$B$5:$B$13,0)) -> 174700 | E32: =C32*D32 -> 0
A33: Tukang besi | B33: TBS | C33: =SUMIFS(AHSP!$L$5:$L$3000,AHSP!$I$5:$I$3000,"II",AHSP!$C$5:$C$3000,B33,AHSP!$J$5:$J$3000,"Upah") -> 0 | D33: =INDEX('Perhitungan Upah'!$C$5:$C$13,MATCH(B33,'Perhitungan Upah'!$B$5:$B$13,0)) -> 174700 | E33: =C33*D33 -> 0
A34: Tukang cat | B34: TCT | C34: =SUMIFS(AHSP!$L$5:$L$3000,AHSP!$I$5:$I$3000,"II",AHSP!$C$5:$C$3000,B34,AHSP!$J$5:$J$3000,"Upah") -> 0 | D34: =INDEX('Perhitungan Upah'!$C$5:$C$13,MATCH(B34,'Perhitungan Upah'!$B$5:$B$13,0)) -> 165000 | E34: =C34*D34 -> 0
A35: Tukang listrik | B35: TLS | C35: =SUMIFS(AHSP!$L$5:$L$3000,AHSP!$I$5:$I$3000,"II",AHSP!$C$5:$C$3000,B35,AHSP!$J$5:$J$3000,"Upah") -> 0 | D35: =INDEX('Perhitungan Upah'!$C$5:$C$13,MATCH(B35,'Perhitungan Upah'!$B$5:$B$13,0)) -> 182800 | E35: =C35*D35 -> 0
A36: Tukang pipa | B36: TPP | C36: =SUMIFS(AHSP!$L$5:$L$3000,AHSP!$I$5:$I$3000,"II",AHSP!$C$5:$C$3000,B36,AHSP!$J$5:$J$3000,"Upah") -> 0 | D36: =INDEX('Perhitungan Upah'!$C$5:$C$13,MATCH(B36,'Perhitungan Upah'!$B$5:$B$13,0)) -> 184400 | E36: =C36*D36 -> 0
A37: Kepala tukang | B37: KTK | C37: =SUMIFS(AHSP!$L$5:$L$3000,AHSP!$I$5:$I$3000,"II",AHSP!$C$5:$C$3000,B37,AHSP!$J$5:$J$3000,"Upah") -> 0.491265 | D37: =INDEX('Perhitungan Upah'!$C$5:$C$13,MATCH(B37,'Perhitungan Upah'!$B$5:$B$13,0)) -> 198900 | E37: =C37*D37 -> 97712.609
A38: Mandor | B38: MDR | C38: =SUMIFS(AHSP!$L$5:$L$3000,AHSP!$I$5:$I$3000,"II",AHSP!$C$5:$C$3000,B38,AHSP!$J$5:$J$3000,"Upah") -> 1.2786233 | D38: =INDEX('Perhitungan Upah'!$C$5:$C$13,MATCH(B38,'Perhitungan Upah'!$B$5:$B$13,0)) -> 228300 | E38: =C38*D38 -> 291909.69
A39: III. STRUKTUR BETON | C39: =SUM(C40:C48) -> 29.194374 | E39: =SUM(E40:E48) -> 4387790.1
A40: Pekerja | B40: PKJ | C40: =SUMIFS(AHSP!$L$5:$L$3000,AHSP!$I$5:$I$3000,"III",AHSP!$C$5:$C$3000,B40,AHSP!$J$5:$J$3000,"Upah") -> 17.750218 | D40: =INDEX('Perhitungan Upah'!$C$5:$C$13,MATCH(B40,'Perhitungan Upah'!$B$5:$B$13,0)) -> 130500 | E40: =C40*D40 -> 2316403.4
A41: Tukang batu | B41: TKG | C41: =SUMIFS(AHSP!$L$5:$L$3000,AHSP!$I$5:$I$3000,"III",AHSP!$C$5:$C$3000,B41,AHSP!$J$5:$J$3000,"Upah") -> 0.35682283 | D41: =INDEX('Perhitungan Upah'!$C$5:$C$13,MATCH(B41,'Perhitungan Upah'!$B$5:$B$13,0)) -> 175300 | E41: =C41*D41 -> 62551.042
A42: Tukang kayu | B42: TKY | C42: =SUMIFS(AHSP!$L$5:$L$3000,AHSP!$I$5:$I$3000,"III",AHSP!$C$5:$C$3000,B42,AHSP!$J$5:$J$3000,"Upah") -> 6.3897329 | D42: =INDEX('Perhitungan Upah'!$C$5:$C$13,MATCH(B42,'Perhitungan Upah'!$B$5:$B$13,0)) -> 174700 | E42: =C42*D42 -> 1116286.3
...

Sheet AHSP
A1: ANALISA HARGA SATUAN PEKERJAAN (AHSP)
A2: Upah di AHSP = upah per volume (dipakai RAB Borongan); swakelola membayar per hari — lihat Perhitungan Upah. Format Permen PUPR: A. Tenaga kerja, B. Bahan, C. Jumlah, D. Margin, E. Harga satuan. Koefisien = koefisien pasar terkalibrasi, bahan sudah termasuk susut (biru, boleh diubah).
A4: No | B4: Uraian | C4: Kode | D4: Satuan | E4: Koefisien | F4: Harga satuan | G4: Jumlah harga | H4: Bantu: item | I4: Bantu: tahap | J4: Bantu: jenis | K4: Bantu: volume | L4: Bantu: total kebutuhan
A5: I.1 | B5: Bouwplank & pengukuran — per 1 m² | J5: Volume RAB: | K5: =Volume!$B$23 -> 36
A6: A | B6: TENAGA KERJA
B7: Tukang kayu | C7: TKY | D7: OH | E7: 0.05 | F7: =INDEX('Perhitungan Upah'!$C$5:$C$13,MATCH(C7,'Perhitungan Upah'!$B$5:$B$13,0)) -> 174700 | G7: =E7*F7 -> 8735 | H7: I.1 | I7: I | J7: Upah | K7: =$K$5 -> 36 | L7: =E7*K7 -> 1.8
B8: Pekerja | C8: PKJ | D8: OH | E8: 0.05 | F8: =INDEX('Perhitungan Upah'!$C$5:$C$13,MATCH(C8,'Perhitungan Upah'!$B$5:$B$13,0)) -> 130500 | G8: =E8*F8 -> 6525 | H8: I.1 | I8: I | J8: Upah | K8: =$K$5 -> 36 | L8: =E8*K8 -> 1.8
B9: Jumlah tenaga kerja | G9: =SUM(G7:G8) -> 15260
A10: B | B10: BAHAN
B11: Kayu bouwplank | C11: KYB | D11: m² | E11: 1 | F11: =VLOOKUP(C11,'Perhitungan Bahan'!$A$5:$J$61,10,FALSE()) -> 3000 | G11: =E11*F11 -> 3000 | H11: I.1 | I11: I | J11: Bahan | K11: =$K$5 -> 36 | L11: =E11*K11 -> 36
B12: Jumlah bahan | G12: =SUM(G11:G11) -> 3000
A13: C | B13: HARGA SATUAN SWAKELOLA (A + B) | G13: =G9+G12 -> 18260
A14: D | B14: Margin kontraktor | E14: =Parameter!$B$4 -> 0.15 | G14: =G13*E14 -> 2739
A15: E | B15: HARGA SATUAN BORONGAN (C + D) | G15: =G13+G14 -> 20999
A17: I.2 | B17: Pembersihan lahan — per 1 ls | J17: Volume RAB: | K17: 1
A18: A | B18: TENAGA KERJA
B19: Pekerja | C19: PKJ | D19: OH | E19: 15 | F19: =INDEX('Perhitungan Upah'!$C$5:$C$13,MATCH(C19,'Perhitungan Upah'!$B$5:$B$13,0)) -> 130500 | G19: =E19*F19 -> 1957500 | H19: I.2 | I19: I | J19: Upah | K19: =$K$17 -> 1 | L19: =E19*K19 -> 15
B20: Jumlah tenaga kerja | G20: =SUM(G19:G19) -> 1957500
A21: B | B21: BAHAN
B22: Jumlah bahan | G22: 0
A23: C | B23: HARGA SATUAN SWAKELOLA (A + B) | G23: =G20+G22 -> 1957500
A24: D | B24: Margin kontraktor | E24: =Parameter!$B$4 -> 0.15 | G24: =G23*E24 -> 293625
A25: E | B25: HARGA SATUAN BORONGAN (C + D) | G25: =G23+G24 -> 2251125
A27: I.3 | B27: Air & listrik kerja — per 1 ls | J27: Volume RAB: | K27: 1
A28: A | B28: TENAGA KERJA
B29: Jumlah tenaga kerja | G29: 0
A30: B | B30: BAHAN
B31: Air & listrik kerja | C31: AIR | D31: lot | E31: 1 | F31: =VLOOKUP(C31,'Perhitungan Bahan'!$A$5:$J$61,10,FALSE()) -> 1500000 | G31: =E31*F31 -> 1500000 | H31: I.3 | I31: I | J31: Bahan | K31: =$K$27 -> 1 | L31: =E31*K31 -> 1
B32: Jumlah bahan | G32: =SUM(G31:G31) -> 1500000
A33: C | B33: HARGA SATUAN SWAKELOLA (A + B) | G33: =G29+G32 -> 1500000
A34: D | B34: Margin kontraktor | E34: =Parameter!$B$4 -> 0.15 | G34: =G33*E34 -> 225000
A35: E | B35: HARGA SATUAN BORONGAN (C + D) | G35: =G33+G34 -> 1725000
A37: II.1 | B37: Galian tanah pondasi — per 1 m³ | J37: Volume RAB: | K37: =Volume!$B$31 -> 24.84
A38: A | B38: TENAGA KERJA
B39: Pekerja | C39: PKJ | D39: OH | E39: 0.6375 | F39: =INDEX('Perhitungan Upah'!$C$5:$C$13,MATCH(C39,'Perhitungan Upah'!$B$5:$B$13,0)) -> 130500 | G39: =E39*F39 -> 83193.75 | H39: II.1 | I39: II | J39: Upah | K39: =$K$37 -> 24.84 | L39: =E39*K39 -> 15.8355
B40: Mandor | C40: MDR | D40: OH | E40: 0.0213 | F40: =INDEX('Perhitungan Upah'!$C$5:$C$13,MATCH(C40,'Perhitungan Upah'!$B$5:$B$13,0)) -> 228300 | G40: =E40*F40 -> 4862.79 | H40: II.1 | I40: II | J40: Upah | K40: =$K$37 -> 24.84 | L40: =E40*K40 -> 0.529092
B41: Jumlah tenaga kerja | G41: =SUM(G39:G40) -> 88056.54
A42: B | B42: BAHAN
B43: Jumlah bahan | G43: 0
A44: C | B44: HARGA SATUAN SWAKELOLA (A + B) | G44: =G41+G43 -> 88056.54
...

Sheet Kurva-S
A1: JADWAL & KURVA-S — rencana vs realisasi
A2: Isi progres kumulatif (%) tiap tahap setiap akhir minggu. Mulai tahap pertama bisa diubah (biru).
A3: Minggu berjalan | B3: 4
A5: Tahap | B5: Bobot | C5: Mulai (minggu) | D5: Durasi (minggu) | E5: M1 | F5: M2 | G5: M3 | H5: M4 | I5: M5 | J5: M6 | K5: M7 | L5: M8 | M5: M9 | N5: M10 | O5: M11 | P5: M12 | Q5: M13 | R5: M14 | S5: M15 | T5: M16 | U5: M17 | V5: M18 | W5: M19 | X5: M20 | Y5: M21 | Z5: M22 | AA5: M23 | AB5: M24 | AC5: M25 | AD5: M26 | AE5: M27 | AF5: M28 | AG5: M29 | AH5: M30
A6: I. PERSIAPAN | B6: ='RAB Borongan'!L5/'RAB Borongan'!L73 -> 0.020298107 | C6: 1 | D6: ='Perhitungan Upah'!E154 -> 1 | E6: =IF(AND(1>=$C6,1<$C6+$D6),$B6/$D6,0) -> 0.020298107 | F6: =IF(AND(2>=$C6,2<$C6+$D6),$B6/$D6,0) -> 0 | G6: =IF(AND(3>=$C6,3<$C6+$D6),$B6/$D6,0) -> 0 | H6: =IF(AND(4>=$C6,4<$C6+$D6),$B6/$D6,0) -> 0 | I6: =IF(AND(5>=$C6,5<$C6+$D6),$B6/$D6,0) -> 0 | J6: =IF(AND(6>=$C6,6<$C6+$D6),$B6/$D6,0) -> 0 | K6: =IF(AND(7>=$C6,7<$C6+$D6),$B6/$D6,0) -> 0 | L6: =IF(AND(8>=$C6,8<$C6+$D6),$B6/$D6,0) -> 0 | M6: =IF(AND(9>=$C6,9<$C6+$D6),$B6/$D6,0) -> 0 | N6: =IF(AND(10>=$C6,10<$C6+$D6),$B6/$D6,0) -> 0 | O6: =IF(AND(11>=$C6,11<$C6+$D6),$B6/$D6,0) -> 0 | P6: =IF(AND(12>=$C6,12<$C6+$D6),$B6/$D6,0) -> 0 | Q6: =IF(AND(13>=$C6,13<$C6+$D6),$B6/$D6,0) -> 0 | R6: =IF(AND(14>=$C6,14<$C6+$D6),$B6/$D6,0) -> 0 | S6: =IF(AND(15>=$C6,15<$C6+$D6),$B6/$D6,0) -> 0 | T6: =IF(AND(16>=$C6,16<$C6+$D6),$B6/$D6,0) -> 0 | U6: =IF(AND(17>=$C6,17<$C6+$D6),$B6/$D6,0) -> 0 | V6: =IF(AND(18>=$C6,18<$C6+$D6),$B6/$D6,0) -> 0 | W6: =IF(AND(19>=$C6,19<$C6+$D6),$B6/$D6,0) -> 0 | X6: =IF(AND(20>=$C6,20<$C6+$D6),$B6/$D6,0) -> 0 | Y6: =IF(AND(21>=$C6,21<$C6+$D6),$B6/$D6,0) -> 0 | Z6: =IF(AND(22>=$C6,22<$C6+$D6),$B6/$D6,0) -> 0 | AA6: =IF(AND(23>=$C6,23<$C6+$D6),$B6/$D6,0) -> 0 | AB6: =IF(AND(24>=$C6,24<$C6+$D6),$B6/$D6,0) -> 0 | AC6: =IF(AND(25>=$C6,25<$C6+$D6),$B6/$D6,0) -> 0 | AD6: =IF(AND(26>=$C6,26<$C6+$D6),$B6/$D6,0) -> 0 | AE6: =IF(AND(27>=$C6,27<$C6+$D6),$B6/$D6,0) -> 0 | AF6: =IF(AND(28>=$C6,28<$C6+$D6),$B6/$D6,0) -> 0 | AG6: =IF(AND(29>=$C6,29<$C6+$D6),$B6/$D6,0) -> 0 | AH6: =IF(AND(30>=$C6,30<$C6+$D6),$B6/$D6,0) -> 0
